Workbook

Sheet EV
B2: Start Date | C2: 42005
B3: End Date | C3: =TODAY() -> 46065
B4: Periods | C4: M
C6: EV | D6: EV | E6: EV | F6: EV | G6: EV | H6: EV | I6: EV | J6: EV | K6: EV | L6: EV | M6: EV | N6: EV | O6: EV | P6: EV | Q6: EV | R6: EV | S6: EV | T6: EV | U6: EV | V6: EV | W6: EV | X6: EV | Y6: EV | Z6: EV | AA6: EV | AB6: EV | AC6: EV | AD6: EV | AE6: EV | AF6: EV | AG6: EV | AH6: EV | AI6: EV | AJ6: EV | AK6: EV | AL6: EV | AM6: EV | AN6: EV | AO6: EV | AP6: EV | AQ6: EV | AR6: EV | AS6: EV | AT6: EV | AU6: EV | AV6: EV | AW6: EV | AX6: EV | AY6: EV | AZ6: EV | BA6: x | KJ6: x
C7: ADBE US Equity | D7: AKAM US Equity | E7: APPF US Equity | F7: AXON US Equity | G7: CRM US Equity | H7: CRWD US Equity | I7: CYBR US Equity | J7: DDOG US Equity | K7: DOCN US Equity | L7: DT US Equity | M7: ESTC US Equity | N7: FIG US Equity | O7: FROG US Equity | P7: GTLB US Equity | Q7: HUBS US Equity | R7: IOT US Equity | S7: KVYO US Equity | T7: MDB US Equity | U7: MNDY US Equity | V7: NET US Equity | W7: NOW US Equity | X7: PLTR US Equity | Y7: PTC US Equity | Z7: QLYS US Equity | AA7: RBRK US Equity | AB7: SAIL US Equity | AC7: SHOP US Equity | AD7: SNOW US Equity | AE7: TEAM US Equity | AF7: TTAN US Equity | AG7: VEEV Us Equity | AH7: WDAY US Equity | AI7: ZETA US Equity | AJ7: OKTA US Equity | AK7: CFLT US Equity | AL7: MSFT US Equity | AM7: PATH US Equity | AN7: ZS US Equity | AO7: FTNT US Equity | AP7: PANW US Equity | AQ7: ORCL US Equity | AR7: GLBE US Equity | AS7: ADSK US Equity | AT7: PCOR US Equity | AU7: INTU US Equity | AV7: FRSH US Equity | AW7: PAYC US Equity | AX7: S US Equity | AY7: NCNO US Equity | AZ7: BILL US Equity | BA7: NVDA US Equity | BB7: GOOG US Equity | BC7: MSFT US Equity | BD7: AMZN US Equity | BE7: META US Equity | BF7: AVGO US Equity | BG7: LLY US Equity | BH7: ORCL US Equity | BI7: BABA US Equity | BJ7: PLTR US Equity | BK7: NFLX US Equity | BL7: CRM US Equity | BM7: APH US Equity | BN7: ANET US Equity | BO7: UBER US Equity | BP7: APP US Equity | BQ7: BKNG US Equity | BR7: WELL US Equity | BS7: NEM US Equity | BT7: IBKR US Equity | BU7: INTU US Equity | BV7: PANW US Equity | BW7: NOW US Equity | BX7: ADBE US Equity | BY7: CRWD US Equity | BZ7: SPOT US Equity | CA7: KKR US Equity | CB7: NU US Equity | CC7: DASH US Equity | CD7: CVNA US Equity | CE7: HWM US Equity | CF7: BK US Equity | CG7: SNPS US Equity | CH7: HOOD US Equity | CI7: ABNB US Equity | CJ7: APO US Equity | CK7: CDNS US Equity | CL7: PWR US Equity | CM7: VRT US Equity | CN7: NET US Equity | CO7: SNOW US Equity | CP7: FTNT US Equity | CQ7: MPWR US Equity | CR7: ADSK US Equity | CS7: ALNY US Equity | CT7: CCL US Equity | CU7: ARES US Equity | CV7: FIX US Equity | CW7: WDAY US Equity | CX7: DDOG US Equity | CY7: EBAY US Equity | CZ7: TCOM US Equity | DA7: HEI US Equity | DB7: BE US Equity | DC7: TKO US Equity | DD7: PYPL US Equity | DE7: AXON US Equity | DF7: CPNG US Equity | DG7: XYZ US Equity | DH7: LYV US Equity | DI7: FICO US Equity | DJ7: RDDT US Equity | DK7: LPLA US Equity | DL7: ZS US Equity | DM7: FTAI US Equity | DN7: EXPE US Equity | DO7: MDB US Equity | DP7: DXCM US Equity | DQ7: TEAM US Equity | DR7: SOFI US Equity | DS7: ZM US Equity | DT7: FSLR US Equity | DU7: FTI US Equity | DV7: RGLD US Equity | DW7: WWD US Equity | DX7: AFRM US Equity | DY7: CRDO US Equity | DZ7: INCY US Equity | EA7: MTZ US Equity | EB7: OWL US Equity | EC7: BURL US Equity | ED7: CHKP US Equity | EE7: SMCI US Equity | EF7: PODD US Equity | EG7: ATI US Equity | EH7: CRS US Equity | EI7: TOST US Equity | EJ7: TWLO US Equity | EK7: FN US Equity | EL7: MEDP US Equity | EM7: BBIO US Equity | EN7: OKTA US Equity | EO7: ONON US Equity | EP7: Z US Equity | EQ7: IOT US Equity | ER7: PINS US Equity | ES7: PEN US Equity | ET7: ROKU US Equity | EU7: NBIX US Equity | EV7: W US Equity | EW7: DKNG US Equity | EX7: AKAM US Equity | EY7: TTD US Equity | EZ7: CELH US Equity | FA7: HUBS US Equity | FB7: GDDY US Equity | FC7: RYAN US Equity | FD7: DY US Equity | FE7: RBRK US Equity | FF7: EXEL US Equity | FG7: CHWY US Equity | FH7: U US Equity | FI7: BMRN US Equity | FJ7: GWRE US Equity | FK7: CFLT US Equity | FL7: MOD US Equity | FM7: DT US Equity | FN7: NCLH US Equity | FO7: FLS US Equity | FP7: NTNX US Equity | FQ7: CART US Equity | FR7: AXSM US Equity | FS7: DOCU US Equity | FT7: KNSL US Equity | FU7: HALO US Equity | FV7: BROS US Equity | FW7: PRIM US Equity | FX7: PL US Equity | FY7: PCOR US Equity | FZ7: WING US Equity | GA7: AAON US Equity | GB7: PLNT US Equity | GC7: RYTM US Equity | GD7: EAT US Equity | GE7: HQY US Equity | GF7: PAYC US Equity | GG7: CWAN US Equity | GH7: PCTY US Equity | GI7: LYFT US Equity | GJ7: MTCH US Equity | GK7: FSS US Equity | GL7: ROAD US Equity | GM7: SFM US Equity | GN7: HXL US Equity | GO7: PATH US Equity | GP7: LTH US Equity | GQ7: DBX US Equity | GR7: KVYO US Equity | GS7: ALK US Equity | GT7: ESTC US Equity | GU7: TTAN US Equity | GV7: LMND US Equity | GW7: FROG US Equity | GX7: FLNC US Equity | GY7: HIMS US Equity | GZ7: NE US Equity | HA7: OS US Equity | HB7: DUOL US Equity | HC7: GTLB US Equity | HD7: RDNT US Equity | HE7: DOCN US Equity | HF7: ETSY US Equity | HG7: CNX US Equity | HH7: MNDY US Equity | HI7: LAUR US Equity | HJ7: KD US Equity | HK7: BFAM US Equity | HL7: CRSP US Equity | HM7: FOUR US Equity | HN7: PI US Equity | HO7: TGTX US Equity | HP7: TCBI US Equity | HQ7: CALM US Equity | HR7: STNE US Equity | HS7: S US Equity | HT7: ZETA US Equity | HU7: MYRG US Equity | HV7: SEI US Equity | HW7: SHAK US Equity | HX7: ACMR US Equity | HY7: KC US Equity | HZ7: BILL US Equity | IA7: OSCR US Equity | IB7: LRN US Equity | IC7: QTWO US Equity | ID7: DAN US Equity | IE7: ATGE US Equity | IF7: COCO US Equity | IG7: TDW US Equity | IH7: PLMR US Equity | II7: ARQT US Equity | IJ7: XMTR US Equity | IK7: VRNS US Equity | IL7: OPLN US Equity | IM7: CPRX US Equity | IN7: TVTX US Equity | IO7: BWIN US Equity | IP7: ATRO US Equity | IQ7: FRSH US Equity | IR7: TARS US Equity | IS7: PRVA US Equity | IT7: BL US Equity | IU7: CHEF US Equity | IV7: CECO US Equity | IW7: TENB US Equity | IX7: RARE US Equity | IY7: UPWK US Equity | IZ7: INTA US Equity | JA7: ASAN US Equity | JB7: DXPE US Equity | JC7: HRMY US Equity | JD7: NCNO US Equity | JE7: BRZE US Equity | JF7: NESR US Equity | JG7: PGNY US Equity | JH7: MNKD US Equity | JI7: AAMI US Equity | JJ7: ALKT US Equity | JK7: CDRE US Equity | JL7: ALGT US Equity | JM7: PAHC US Equity | JN7: BCRX US Equity | JO7: PRCT US Equity | JP7: YELP US Equity | JQ7: XPEL US Equity | JR7: TRIP US Equity | JS7: FLYW US Equity | JT7: CCB US Equity | JU7: FSLY US Equity | JV7: VITL US Equity | JW7: AMPL US Equity | JX7: CDNA US Equity | JY7: COUR US Equity | JZ7: SNCY US Equity | KA7: NRDS US Equity | KB7: PD US Equity | KC7: SG US Equity | KD7: CARS US Equity | KE7: NTGR US Equity | KF7: GOGO US Equity | KG7: WEAV US Equity | KH7: SPT US Equity | KI7: EOLS US Equity | KJ7: x
C8: =_xll.BQL(C$7, "curr_entp_val(as_of_date=range(2015-01-01, 2026-02-12, frq=M), mode=CACHED)", "showdates", "false", "showheaders", "false","cols=1;rows=136") -> ADBE US Equity | D8: =_xll.BQL(D$7, "curr_entp_val(as_of_date=range(2015-01-01, 2026-02-12, frq=M), mode=CACHED)", "showdates", "false", "showheaders", "false","cols=1;rows=136") -> AKAM US Equity | E8: =_xll.BQL(E$7, "curr_entp_val(as_of_date=range(2015-01-01, 2026-02-12, frq=M), mode=CACHED)", "showdates", "false", "showheaders", "false","cols=1;rows=136") -> APPF US Equity | F8: =_xll.BQL(F$7, "curr_entp_val(as_of_date=range(2015-01-01, 2026-02-12, frq=M), mode=CACHED)", "showdates", "false", "showheaders", "false","cols=1;rows=136") -> AXON US Equity | G8: =_xll.BQL(G$7, "curr_entp_val(as_of_date=range(2015-01-01, 2026-02-12, frq=M), mode=CACHED)", "showdates", "false", "showheaders", "false","cols=1;rows=136") -> CRM US Equity | H8: =_xll.BQL(H$7, "curr_entp_val(as_of_date=range(2015-01-01, 2026-02-12, frq=M), mode=CACHED)", "showdates", "false", "showheaders", "false","cols=1;rows=136") -> CRWD US Equity | I8: =_xll.BQL(I$7, "curr_entp_val(as_of_date=range(2015-01-01, 2026-02-12, frq=M), mode=CACHED)", "showdates", "false", "showheaders", "false","cols=1;rows=136") -> CYBR US Equity | J8: =_xll.BQL(J$7, "curr_entp_val(as_of_date=range(2015-01-01, 2026-02-12, frq=M), mode=CACHED)", "showdates", "false", "showheaders", "false","cols=1;rows=136") -> DDOG US Equity | ... KI8: =_xll.BQL(KI$7, "curr_entp_val(as_of_date=range(2015-01-01, 2026-02-12, frq=M), mode=CACHED)", "showdates", "false", "showheaders", "false","cols=1;rows=136") -> EOLS US Equity | KJ8: x
B9: 42005 | C9: 34033140288 | D9: 10244838328 | E9: #N/A | F9: 1323123224 | G9: 37714453328 | H9: #N/A | I9: 1003851288 | J9: #N/A | K9: #N/A | L9: #N/A | M9: #N/A | N9: #N/A | O9: #N/A | P9: #N/A | Q9: 1162180088 | R9: #N/A | S9: #N/A | T9: #N/A | U9: #N/A | V9: #N/A | W9: 9852414752 | X9: #N/A | Y9: 4569444808 | Z9: 1144429936 | AA9: #N/A | AB9: #N/A | AC9: #N/A | AD9: #N/A | AE9: #N/A | AF9: #N/A | AG9: 3056147504 | AH9: 13915947336 | AI9: #N/A | AJ9: #N/A | AK9: #N/A | AL9: 317407514048 | AM9: #N/A | AN9: #N/A | AO9: 4393891944 | AP9: 9283862096 | AQ9: 185621776256 | AR9: #N/A | AS9: 12254981664 | AT9: #N/A | AU9: 25229915008 | AV9: #N/A | AW9: 1354503336 | AX9: #N/A | AY9: #N/A | AZ9: #N/A | BA9: 8049353880 | BB9: 301502447232 | BC9: 317407514048 | BD9: 140774053376 | BE9: 203535905536 | BF9: 29588798016 | BG9: 77624423840 | BH9: 185621776256 | BI9: 1.5377729e+12 | BJ9: #N/A | BK9: 19813946696 | BL9: 37714453328 | BM9: 18053200128 | BN9: 3548725880 | BO9: #N/A | BP9: #N/A | BQ9: 57384808184 | BR9: 35471742136 | BS9: 17058237888 | BT9: 18062462928 | BU9: 25229915008 | BV9: 9283862096 | BW9: 9852414752 | BX9: 34033140288 | BY9: #N/A | BZ9: #N/A | CA9: 65384484952 | CB9: #N/A | CC9: #N/A | CD9: #N/A | CE9: #N/A | CF9: #N/A | CG9: 5744639984 | CH9: #N/A | CI9: #N/A | CJ9: 19736809320 | CK9: 5295156560 | CL9: 5990153400 | CM9: #N/A | CN9: #N/A | CO9: #N/A | CP9: 4393891944 | CQ9: 1698515832 | CR9: 12254981664 | CS9: 6505848032 | CT9: 43992659776 | CU9: 22863222944 | CV9: 654737504 | CW9: 13915947336 | CX9: #N/A | CY9: 66926653248 | CZ9: 3.7236094e+10 | DA9: 3925842376 | DB9: #N/A | DC9: 367688040 | DD9: #N/A | DE9: 1323123224 | DF9: #N/A | DG9: #N/A | DH9: 6207018400 | DI9: 2753449136 | DJ9: #N/A | DK9: 5634511408 | DL9: #N/A | DM9: #N/A | DN9: 10537592040 | DO9: #N/A | DP9: 4145030752 | DQ9: #N/A | DR9: #N/A | DS9: #N/A | DT9: 3571772248 | DU9: 11808967552 | DV9: 3696151608 | DW9: 3806201000 | DX9: #N/A | DY9: #N/A | DZ9: 12500293520 | EA9: 3009054288 | EB9: #N/A | EC9: 4919783456 | ED9: 11334416792 | EE9: 1523809256 | EF9: 2611243192 | EG9: 5162501664 | EH9: 3160154816 | EI9: #N/A | EJ9: #N/A | EK9: 396912904 | EL9: #N/A | EM9: #N/A | EN9: #N/A | EO9: #N/A | EP9: 3939153024 | EQ9: #N/A | ER9: #N/A | ES9: #N/A | ET9: #N/A | EU9: 1521069200 | EV9: 1912969008 | EW9: #N/A | EX9: 10244838328 | EY9: #N/A | EZ9: 10330630 | FA9: 1162180088 | FB9: #N/A | FC9: #N/A | FD9: 1646022688 | FE9: #N/A | FF9: 444323752 | FG9: #N/A | FH9: #N/A | FI9: 13321396632 | FJ9: 3023049736 | FK9: #N/A | FL9: 744107136 | FM9: #N/A | FN9: 13894910704 | FO9: 9168002512 | FP9: #N/A | FQ9: #N/A | FR9: #N/A | FS9: #N/A | FT9: #N/A | FU9: 1125358408 | FV9: #N/A | FW9: 1294636848 | FX9: #N/A | FY9: #N/A | FZ9: #N/A | GA9: 1184718256 | GB9: #N/A | GC9: #N/A | GD9: 4559622560 | GE9: 1285628624 | GF9: 1354503336 | GG9: #N/A | GH9: 1241201160 | GI9: #N/A | GJ9: #N/A | GK9: 1005903968 | GL9: #N/A | GM9: 5406492944 | GN9: 4353363296 | GO9: #N/A | GP9: #N/A | GQ9: #N/A | GR9: #N/A | GS9: 7408085120 | GT9: #N/A | GU9: #N/A | GV9: #N/A | GW9: #N/A | GX9: #N/A | GY9: #N/A | GZ9: #N/A | HA9: #N/A | HB9: #N/A | HC9: #N/A | HD9: 9.8038015e+08 | HE9: #N/A | HF9: #N/A | HG9: 10848354304 | HH9: #N/A | HI9: #N/A | HJ9: #N/A | HK9: 3753777224 | HL9: #N/A | HM9: #N/A | HN9: #N/A | HO9: 629343029 | HP9: #N/A | HQ9: 1743855000 | HR9: #N/A | HS9: #N/A | HT9: #N/A | HU9: 504741592 | HV9: #N/A | HW9: #N/A | HX9: #N/A | HY9: #N/A | HZ9: #N/A | IA9: #N/A | IB9: 380605552 | IC9: 555070256 | ID9: 4095576384 | IE9: 2562478232 | IF9: #N/A | IG9: #N/A | IH9: #N/A | II9: #N/A | IJ9: #N/A | IK9: 691271800 | IL9: 6422494240 | IM9: 163836737 | IN9: 372307025 | IO9: #N/A | IP9: 1394835000 | IQ9: #N/A | IR9: #N/A | IS9: #N/A | IT9: #N/A | IU9: 716985056 | IV9: 468221944 | IW9: #N/A | IX9: 1198519920 | IY9: #N/A | IZ9: #N/A | JA9: #N/A | JB9: 1172265672 | JC9: #N/A | JD9: #N/A | JE9: #N/A | JF9: #N/A | JG9: #N/A | JH9: 2164525800 | JI9: 8248000000 | JJ9: #N/A | JK9: #N/A | JL9: 2877226800 | JM9: 1497951440 | JN9: 776730384 | JO9: #N/A | JP9: 3551230152 | JQ9: 76770364 | JR9: 10402726144 | JS9: #N/A | JT9: #N/A | JU9: #N/A | JV9: #N/A | JW9: #N/A | JX9: 59255256 | JY9: #N/A | JZ9: #N/A | KA9: #N/A | KB9: #N/A | KC9: #N/A | KD9: #N/A | KE9: 987957952 | KF9: 1480301936 | KG9: #N/A | KH9: #N/A | KI9: #N/A
B10: 42036 | C10: 32721588800 | D10: 9389577144 | E10: #N/A | F10: 1350957208 | G10: 35909792592 | H10: #N/A | I10: 832876952 | J10: #N/A | K10: #N/A | L10: #N/A | M10: #N/A | N10: #N/A | O10: #N/A | P10: #N/A | Q10: 1163435640 | R10: #N/A | S10: #N/A | T10: #N/A | U10: #N/A | V10: #N/A | W10: 10586043464 | X10: #N/A | Y10: 4184278344 | Z10: 1153426544 | AA10: #N/A | AB10: #N/A | AC10: #N/A | AD10: #N/A | AE10: #N/A | AF10: #N/A | AG10: 3363045680 | AH10: 13513897288 | AI10: #N/A | AJ10: #N/A | AK10: #N/A | AL10: 269491919040 | AM10: #N/A | AN10: #N/A | AO10: 4208348128 | AP10: 9591547472 | AQ10: 172096374656 | AR10: #N/A | AS10: 10877345312 | AT10: #N/A | AU10: 23696800640 | AV10: #N/A | AW10: 1417583656 | AX10: #N/A | AY10: #N/A | AZ10: #N/A | BA10: 7590065304 | BB10: 304387133056 | BC10: 269491919040 | BD10: 163311031872 | BE10: 201506987648 | BF10: 30173508160 | BG10: #N/A | BH10: 172096374656 | BI10: 1.3103479e+12 | BJ10: #N/A | BK10: 26049156736 | BL10: 35909792592 | BM10: 17996189824 | BN10: 3700770168 | BO10: #N/A | BP10: #N/A | BQ10: 50540306168 | BR10: 37529535672 | BS10: 20175710656 | BT10: 13103117088 | BU10: 23696800640 | BV10: 9591547472 | BW10: 10586043464 | BX10: 32721588800 | BY10: #N/A | BZ10: #N/A | CA10: 65727390808 | CB10: #N/A | CC10: #N/A | CD10: #N/A | CE10: #N/A | CF10: #N/A | CG10: 5671150064 | CH10: #N/A | CI10: #N/A | CJ10: 19947135592 | CK10: 5008290640 | CL10: 5584347320 | CM10: #N/A | CN10: #N/A | CO10: #N/A | CP10: 4208348128 | CQ10: 1611339512 | CR10: 10877345312 | CS10: 6792674528 | CT10: 43096678208 | CU10: 23254663328 | CV10: 637227424 | CW10: 13513897288 | CX10: #N/A | CY10: 63374448704 | CZ10: 3.9180532e+10 | DA10: 3925816008 | DB10: #N/A | DC10: 360056744 | DD10: #N/A | DE10: 1350957208 | DF10: #N/A | DG10: #N/A | DH10: 5737476512 | DI10: 2745054904 | DJ10: #N/A | DK10: 5298561072 | DL10: #N/A | DM10: #N/A | DN10: 10609723624 | DO10: #N/A | DP10: 4507168352 | DQ10: #N/A | DR10: #N/A | DS10: #N/A | DT10: 3343791960 | DU10: 9620164480 | DV10: 4347621224 | DW10: 3541914320 | DX10: #N/A | DY10: #N/A | DZ10: 13615309712 | EA10: 2674185168 | EB10: #N/A | EC10: 5134121760 | ED10: 11040330488 | EE10: 1651631192 | EF10: 1676365240 | EG10: 4481695104 | EH10: 2635136800 | EI10: #N/A | EJ10: #N/A | EK10: 347110152 | EL10: #N/A | EM10: #N/A | EN10: #N/A | EO10: #N/A | EP10: 3574433920 | EQ10: #N/A | ER10: #N/A | ES10: #N/A | ET10: #N/A | EU10: 2381447696 | EV10: 1888923568 | EW10: #N/A | EX10: 9389577144 | EY10: #N/A | EZ10: 14589212 | FA10: 1163435640 | FB10: #N/A | FC10: #N/A | FD10: 1500251168 | FE10: #N/A | FF10: 528266536 | FG10: #N/A | FH10: #N/A | FI10: 15264933272 | FJ10: 2986167560 | FK10: #N/A | FL10: 676602624 | FM10: #N/A | FN10: 13224112880 | FO10: 8440116176 | FP10: #N/A | FQ10: #N/A | FR10: #N/A | FS10: #N/A | FT10: #N/A | FU10: 1705900616 | FV10: #N/A | FW10: 1064673072 | FX10: #N/A | FY10: #N/A | FZ10: #N/A | GA10: 1153124784 | GB10: #N/A | GC10: #N/A | GD10: 4543098016 | GE10: 1029381200 | GF10: 1417583656 | GG10: #N/A | GH10: 1112866696 | GI10: #N/A | GJ10: #N/A | GK10: 995263520 | GL10: #N/A | GM10: 5774098704 | GN10: 4565066944 | GO10: #N/A | GP10: #N/A | GQ10: #N/A | GR10: #N/A | GS10: 8048730048 | GT10: #N/A | GU10: #N/A | GV10: #N/A | GW10: #N/A | GX10: #N/A | GY10: #N/A | GZ10: #N/A | HA10: #N/A | HB10: #N/A | HC10: #N/A | HD10: 9.5261823e+08 | HE10: #N/A | HF10: #N/A | HG10: 9775602408 | HH10: #N/A | HI10: #N/A | HJ10: #N/A | HK10: 3855403080 | HL10: #N/A | HM10: #N/A | HN10: #N/A | HO10: 559000053 | HP10: #N/A | HQ10: 1551296024 | HR10: #N/A | HS10: #N/A | HT10: #N/A | HU10: 455494840 | HV10: #N/A | HW10: 1628655984 | HX10: #N/A | HY10: #N/A | HZ10: #N/A | IA10: #N/A | IB10: 454352144 | IC10: 522220272 | ID10: 3949326144 | IE10: 2239245464 | IF10: #N/A | IG10: #N/A | IH10: #N/A | II10: #N/A | IJ10: #N/A | IK10: 694711032 | IL10: 6346436128 | IM10: 210837729 | IN10: 385246065 | IO10: #N/A | IP10: 1403256120 | IQ10: #N/A | IR10: #N/A | IS10: #N/A | IT10: #N/A | IU10: 675640160 | IV10: 421146584 | IW10: #N/A | IX10: 1652119152 | IY10: #N/A | IZ10: #N/A | JA10: #N/A | JB10: 1034694408 | JC10: #N/A | JD10: #N/A | JE10: #N/A | JF10: #N/A | JG10: #N/A | JH10: 2624995048 | JI10: 8118400000 | JJ10: #N/A | JK10: #N/A | JL10: #N/A | JM10: 1333560400 | JN10: 634439952 | JO10: #N/A | JP10: 3387337928 | JQ10: 67745628 | JR10: 9309355264 | JS10: #N/A | JT10: #N/A | JU10: #N/A | JV10: #N/A | JW10: #N/A | JX10: 57012600 | JY10: #N/A | JZ10: #N/A | KA10: #N/A | KB10: #N/A | KC10: #N/A | KD10: #N/A | KE10: 925355456 | KF10: 1310196208 | KG10: #N/A | KH10: #N/A | KI10: #N/A
B11: 42064 | C11: 37397819968 | D11: 11348927192 | E11: #N/A | F11: 1152019888 | G11: 43259189184 | H11: #N/A | I11: 1576045496 | J11: #N/A | K11: #N/A | L11: #N/A | M11: #N/A | N11: #N/A | O11: #N/A | P11: #N/A | Q11: 1166280872 | R11: #N/A | S11: #N/A | T11: #N/A | U11: #N/A | V11: #N/A | W11: 11252103240 | X11: #N/A | Y11: 4327367496 | Z11: 1406523568 | AA11: #N/A | AB11: #N/A | AC11: #N/A | AD11: #N/A | AE11: #N/A | AF11: #N/A | AG11: 3638601008 | AH11: 14624499480 | AI11: #N/A | AJ11: #N/A | AK11: #N/A | AL11: 297794984128 | AM11: #N/A | AN11: #N/A | AO11: 4820788192 | AP11: 10866590288 | AQ11: 180571703168 | AR11: #N/A | AS11: 13063717568 | AT11: #N/A | AU11: 26148767488 | AV11: #N/A | AW11: 1718511248 | AX11: #N/A | AY11: #N/A | AZ11: #N/A | BA11: 8765513576 | BB11: 322227637888 | BC11: 297794984128 | BD11: 175213205056 | BE11: 210071953024 | BF11: 35648864960 | BG11: 81210455776 | BH11: 180571703168 | BI11: 1.2528996e+12 | BJ11: #N/A | BK11: 28052248192 | BL11: 43259189184 | BM11: 18888441984 | BN11: 4051976144 | BO11: #N/A | BP11: #N/A | BQ11: 63869825008 | BR11: 38605342992 | BS11: 20119906368 | BT11: 13604729632 | BU11: 26148767488 | BV11: 10866590288 | BW11: 11252103240 | BX11: 37397819968 | BY11: #N/A | BZ11: #N/A | CA11: 66130169656 | CB11: #N/A | CC11: #N/A | CD11: #N/A | CE11: #N/A | CF11: #N/A | CG11: 6518030128 | CH11: #N/A | CI11: #N/A | CJ11: 20000108272 | CK11: 5034175912 | CL11: 6016623944 | CM11: #N/A | CN11: #N/A | CO11: #N/A | CP11: 4820788192 | CQ11: 1804306384 | CR11: 13063717568 | CS11: 7622237912 | CT11: 43137050432 | CU11: 23531845280 | CV11: 720338896 | CW11: 14624499480 | CX11: #N/A | CY11: 67602819136 | CZ11: 3.9189545e+10 | DA11: 3886787776 | DB11: #N/A | DC11: 456842872 | DD11: #N/A | DE11: 1152019888 | DF11: #N/A | DG11: #N/A | DH11: 6193520152 | DI11: 3177789112 | DJ11: #N/A | DK11: 5771526424 | DL11: #N/A | DM11: #N/A | DN11: 12284402512 | DO11: #N/A | DP11: 4629238848 | DQ11: #N/A | DR11: #N/A | DS11: #N/A | DT11: 4217771000 | DU11: 9942782592 | DV11: 4324288872 | DW11: 3798078416 | DX11: #N/A | DY11: #N/A | DZ11: 14834931160 | EA11: 2868142808 | EB11: #N/A | EC11: 5559859232 | ED11: 11662529272 | EE11: 1822765784 | EF11: 1814537760 | EG11: 5036867456 | EH11: 2842901408 | EI11: #N/A | EJ11: #N/A | EK11: 395663536 | EL11: #N/A | EM11: #N/A | EN11: #N/A | EO11: #N/A | EP11: 6239089840 | EQ11: #N/A | ER11: #N/A | ES11: #N/A | ET11: #N/A | EU11: 3063816144 | EV11: 2203172144 | EW11: #N/A | EX11: 11348927192 | EY11: #N/A | EZ11: 21995442 | FA11: 1166280872 | FB11: #N/A | FC11: #N/A | FD11: 1924117968 | FE11: #N/A | FF11: #N/A | FG11: #N/A | FH11: #N/A | FI11: 16545146496 | FJ11: 3373081864 | FK11: #N/A | FL11: 698656000 | FM11: #N/A | FN11: 17127190656 | FO11: 9084640904 | FP11: #N/A | FQ11: #N/A | FR11: #N/A | FS11: #N/A | FT11: #N/A | FU11: 1804956360 | FV11: #N/A | FW11: 1161092848 | FX11: #N/A | FY11: #N/A | FZ11: #N/A | GA11: 1182888800 | GB11: #N/A | GC11: #N/A | GD11: 4603899936 | GE11: 1002004304 | GF11: 1718511248 | GG11: #N/A | GH11: 1419562560 | GI11: #N/A | GJ11: #N/A | GK11: 1071624480 | GL11: #N/A | GM11: 5874032176 | GN11: 4901058752 | GO11: #N/A | GP11: #N/A | GQ11: #N/A | GR11: #N/A | GS11: 7942268032 | GT11: #N/A | GU11: #N/A | GV11: #N/A | GW11: #N/A | GX11: #N/A | GY11: #N/A | GZ11: #N/A | HA11: #N/A | HB11: #N/A | HC11: #N/A | HD11: 9.897765e+08 | HE11: #N/A | HF11: #N/A | HG11: 10534402120 | HH11: #N/A | HI11: #N/A | HJ11: #N/A | HK11: 4179025400 | HL11: #N/A | HM11: #N/A | HN11: #N/A | HO11: 570870453 | HP11: #N/A | HQ11: 1676120600 | HR11: #N/A | HS11: #N/A | HT11: #N/A | HU11: 509728600 | HV11: #N/A | HW11: 1531031024 | HX11: #N/A | HY11: #N/A | HZ11: #N/A | IA11: #N/A | IB11: 558449360 | IC11: 628673728 | ID11: 4088562944 | IE11: 1956255152 | IF11: #N/A | IG11: #N/A | IH11: #N/A | II11: #N/A | IJ11: #N/A | IK11: 651098920 | IL11: 6753856704 | IM11: 256040833 | IN11: 420173137 | IO11: #N/A | IP11: 1688836664 | IQ11: #N/A | IR11: #N/A | IS11: #N/A | IT11: #N/A | IU11: 647325152 | IV11: 434338040 | IW11: #N/A | IX11: 1689924080 | IY11: #N/A | IZ11: #N/A | JA11: #N/A | JB11: 1103841672 | JC11: #N/A | JD11: #N/A | JE11: #N/A | JF11: #N/A | JG11: #N/A | JH11: 2573843008 | JI11: 4537500000 | JJ11: #N/A | JK11: #N/A | JL11: 3431965664 | JM11: 1681442848 | JN11: #N/A | JO11: #N/A | JP11: 3170761616 | JQ11: 80586532 | JR11: 12500205568 | JS11: #N/A | JT11: #N/A | JU11: #N/A | JV11: #N/A | JW11: #N/A | JX11: 45799288 | JY11: #N/A | JZ11: #N/A | KA11: #N/A | KB11: #N/A | KC11: #N/A | KD11: #N/A | KE11: 862075480 | KF11: 1634951896 | KG11: #N/A | KH11: #N/A | KI11: #N/A
B12: 42095 | C12: 36279998000 | D12: 11550367448 | E12: #N/A | F12: 1205743664 | G12: 43038919672 | H12: #N/A | I12: 1461865400 | J12: #N/A | K12: #N/A | L12: #N/A | M12: #N/A | N12: #N/A | O12: #N/A | P12: #N/A | Q12: 1157035176 | R12: #N/A | S12: #N/A | T12: #N/A | U12: #N/A | V12: #N/A | W12: 11160297544 | X12: #N/A | Y12: 4499183176 | Z12: 1468488368 | AA12: #N/A | AB12: #N/A | AC12: #N/A | AD12: #N/A | AE12: #N/A | AF12: #N/A | AG12: 2888923800 | AH12: 14317079320 | AI12: #N/A | AJ12: #N/A | AK12: #N/A | AL12: 272117127360 | AM12: #N/A | AN12: #N/A | AO12: 5031537632 | AP12: 10981980984 | AQ12: 176438974272 | AR12: #N/A | AS12: 11793781440 | AT12: #N/A | AU12: 26161219328 | AV12: #N/A | AW12: 1849859216 | AX12: #N/A | AY12: #N/A | AZ12: #N/A | BA12: 8330645336 | BB12: 312292904576 | BC12: 272117127360 | BD12: 170613478976 | BE12: 217615294080 | BF12: 35166053056 | BG12: 82714490592 | BH12: 176438974272 | BI12: 1.1966203e+12 | BJ12: #N/A | BK12: 24314070656 | BL12: 43038919672 | BM12: 19452999808 | BN12: 4206122984 | BO12: #N/A | BP12: #N/A | BQ12: 59305410544 | BR12: 38772877584 | BS12: 18324125760 | BT12: 19050850608 | BU12: 26161219328 | BV12: 10981980984 | BW12: 11160297544 | BX12: 36279998000 | BY12: #N/A | BZ12: #N/A | CA12: 66229879608 | CB12: #N/A | CC12: #N/A | CD12: #N/A | CE12: #N/A | CF12: #N/A | CG12: 6504198448 | CH12: #N/A | CI12: #N/A | CJ12: 19692852464 | CK12: 5049058216 | CL12: 5699301192 | CM12: #N/A | CN12: #N/A | CO12: #N/A | CP12: 5031537632 | CQ12: 1804014928 | CR12: 11793781440 | CS12: 7934662872 | CT12: 45896273088 | CU12: 22799973936 | CV12: 807550160 | CW12: 14317079320 | CX12: #N/A | CY12: 66807752768 | CZ12: 5.0062079e+10 | DA12: 4047154880 | DB12: #N/A | DC12: 362463672 | DD12: #N/A | DE12: 1205743664 | DF12: #N/A | DG12: #N/A | DH12: 6137100312 | DI12: 3345603256 | DJ12: #N/A | DK12: 5638004760 | DL12: #N/A | DM12: #N/A | DN12: 12591064912 | DO12: #N/A | DP12: 4687374912 | DQ12: #N/A | DR12: #N/A | DS12: #N/A | DT12: 4326587384 | DU12: 9255392384 | DV12: 3989188968 | DW12: 3951516880 | DX12: #N/A | DY12: #N/A | DZ12: 15451569624 | EA12: 2594679896 | EB12: #N/A | EC12: 5601702256 | ED12: 11364773624 | EE12: 1522112600 | EF12: 1821311520 | EG12: 4613944192 | EH12: 2492143520 | EI12: #N/A | EJ12: #N/A | EK12: 439205744 | EL12: #N/A | EM12: #N/A | EN12: #N/A | EO12: #N/A | EP12: 5232788656 | EQ12: #N/A | ER12: #N/A | ES12: #N/A | ET12: #N/A | EU12: 3134714832 | EV12: 2199330504 | EW12: #N/A | EX12: 11550367448 | EY12: #N/A | EZ12: 25036022 | FA12: 1157035176 | FB12: 5258319832 | FC12: #N/A | FD12: 2049978704 | FE12: #N/A | FF12: 726699992 | FG12: #N/A | FH12: #N/A | FI12: 18960246400 | FJ12: 3136005592 | FK12: #N/A | FL12: 724508352 | FM12: #N/A | FN12: 18549521536 | FO12: 8349101704 | FP12: #N/A | FQ12: #N/A | FR12: #N/A | FS12: #N/A | FT12: #N/A | FU12: 1772986568 | FV12: #N/A | FW12: 956068480 | FX12: #N/A | FY12: #N/A | FZ12: #N/A | GA12: 1254783968 | GB12: #N/A | GC12: #N/A | GD12: 4713094944 | GE12: 1262327864 | GF12: 1849859216 | GG12: #N/A | GH12: 1354939840 | GI12: #N/A | GJ12: #N/A | GK12: 1020659200 | GL12: #N/A | GM12: 5622993968 | GN12: 5308956864 | GO12: #N/A | GP12: #N/A | GQ12: #N/A | GR12: #N/A | GS12: 7961645696 | GT12: #N/A | GU12: #N/A | GV12: #N/A | GW12: #N/A | GX12: #N/A | GY12: #N/A | GZ12: #N/A | HA12: #N/A | HB12: #N/A | HC12: #N/A | HD12: 978557728 | HE12: #N/A | HF12: #N/A | HG12: 9460394568 | HH12: #N/A | HI12: #N/A | HJ12: #N/A | HK12: 4042339064 | HL12: #N/A | HM12: #N/A | HN12: #N/A | HO12: 658755308 | HP12: #N/A | HQ12: 1712098888 | HR12: #N/A | HS12: #N/A | HT12: #N/A | HU12: 566460384 | HV12: #N/A | HW12: 1784135968 | HX12: #N/A | HY12: #N/A | HZ12: #N/A | IA12: #N/A | IB12: 516964112 | IC12: 681157312 | ID12: 3946722560 | IE12: 1793585328 | IF12: #N/A | IG12: #N/A | IH12: #N/A | II12: #N/A | IJ12: #N/A | IK12: 499764840 | IL12: 6951647424 | IM12: 315888109 | IN12: 856743446 | IO12: #N/A | IP12: 1759334200 | IQ12: #N/A | IR12: #N/A | IS12: #N/A | IT12: #N/A | IU12: 694639872 | IV12: 384105136 | IW12: #N/A | IX12: 1997764840 | IY12: #N/A | IZ12: #N/A | JA12: #N/A | JB12: 1045439048 | JC12: #N/A | JD12: #N/A | JE12: #N/A | JF12: #N/A | JG12: #N/A | JH12: 2162167352 | JI12: 8312500000 | JJ12: #N/A | JK12: #N/A | JL12: 3362842080 | JM12: 1658048416 | JN12: 679706144 | JO12: #N/A | JP12: 2984554128 | JQ12: 79794739 | JR12: 11512582144 | JS12: #N/A | JT12: #N/A | JU12: #N/A | JV12: #N/A | JW12: #N/A | JX12: 40671428 | JY12: #N/A | JZ12: #N/A | KA12: #N/A | KB12: #N/A | KC12: #N/A | KD12: #N/A | KE12: 883945816 | KF12: 1710027096 | KG12: #N/A | KH12: #N/A | KI12: #N/A
B13: 42125 | C13: 36960364080 | D13: 12447872480 | E13: #N/A | F13: 1636986288 | G13: 48138861560 | H13: #N/A | I13: 1802335032 | J13: #N/A | K13: #N/A | L13: #N/A | M13: #N/A | N13: #N/A | O13: #N/A | P13: #N/A | Q13: 1138532648 | R13: #N/A | S13: #N/A | T13: #N/A | U13: #N/A | V13: #N/A | W13: 11031718184 | X13: #N/A | Y13: 4713931664 | Z13: 1642708144 | AA13: #N/A | AB13: #N/A | AC13: #N/A | AD13: #N/A | AE13: #N/A | AF13: #N/A | AG13: 3150552984 | AH13: 15594939160 | AI13: #N/A | AJ13: #N/A | AK13: #N/A | AL13: 330028271488 | AM13: #N/A | AN13: #N/A | AO13: 5703871736 | AP13: 11746295608 | AQ13: 182683883328 | AR13: #N/A | AS13: 11555340992 | AT13: #N/A | AU13: 26967875328 | AV13: #N/A | AW13: 1865619344 | AX13: #N/A | AY13: #N/A | AZ13: #N/A | BA13: 9363155800 | BB13: 311037141952 | BC13: 330028271488 | BD13: 192775507264 | BE13: 209595582784 | BF13: 34439910080 | BG13: 85251866752 | BH13: 182683883328 | BI13: 1.1780652e+12 | BJ13: #N/A | BK13: 33211260192 | BL13: 48138861560 | BM13: 18975450112 | BN13: 3893663720 | BO13: #N/A | BP13: #N/A | BQ13: 64930394096 | BR13: 37043364112 | BS13: 19956940544 | BT13: 15488933184 | BU13: 26967875328 | BV13: 11746295608 | BW13: 11031718184 | BX13: 36960364080 | BY13: #N/A | BZ13: #N/A | CA13: 66030458680 | CB13: #N/A | CC13: #N/A | CD13: #N/A | CE13: #N/A | CF13: #N/A | CG13: 6622537008 | CH13: #N/A | CI13: #N/A | CJ13: 19926232560 | CK13: 5211076064 | CL13: 5775077448 | CM13: #N/A | CN13: #N/A | CO13: #N/A | CP13: 5703871736 | CQ13: 1859747128 | CR13: 11555340992 | CS13: 8095856856 | CT13: 43657174208 | CU13: 22764003632 | CV13: 805466272 | CW13: 15594939160 | CX13: #N/A | CY13: 70016870400 | CZ13: 5.4268319e+10 | DA13: 3838652352 | DB13: #N/A | DC13: 359894928 | DD13: #N/A | DE13: 1636986288 | DF13: #N/A | DG13: #N/A | DH13: 6244806280 | DI13: 3312933064 | DJ13: #N/A | DK13: 5241685408 | DL13: #N/A | DM13: #N/A | DN13: 13380839264 | DO13: #N/A | DP13: 5242740192 | DQ13: #N/A | DR13: #N/A | DS13: #N/A | DT13: 4538984536 | DU13: 10650812768 | DV13: 3984475040 | DW13: 3725172120 | DX13: #N/A | DY13: #N/A | DZ13: 17708452984 | EA13: 2541461080 | EB13: #N/A | EC13: 5147753840 | ED13: 11696479856 | EE13: 1300109832 | EF13: 1565520544 | EG13: 5154752928 | EH13: 2911598464 | EI13: #N/A | EJ13: #N/A | EK13: 408053616 | EL13: #N/A | EM13: #N/A | EN13: #N/A | EO13: #N/A | EP13: 5258428592 | EQ13: #N/A | ER13: #N/A | ES13: #N/A | ET13: #N/A | EU13: 2665743792 | EV13: 2089520584 | EW13: #N/A | EX13: 12447872480 | EY13: #N/A | EZ13: 57623434 | FA13: 1138532648 | FB13: 5229392088 | FC13: #N/A | FD13: 2010859856 | FE13: #N/A | FF13: 815940264 | FG13: #N/A | FH13: #N/A | FI13: 18229792848 | FJ13: 2973230296 | FK13: #N/A | FL13: 667537472 | FM13: #N/A | FN13: 17417546880 | FO13: 8974664536 | FP13: #N/A | FQ13: #N/A | FR13: #N/A | FS13: #N/A | FT13: #N/A | FU13: 1919820616 | FV13: #N/A | FW13: 1068490112 | FX13: #N/A | FY13: #N/A | FZ13: #N/A | GA13: 1273810656 | GB13: #N/A | GC13: #N/A | GD13: 4400657952 | GE13: 1341071544 | GF13: 1865619344 | GG13: #N/A | GH13: 1278705216 | GI13: #N/A | GJ13: #N/A | GK13: 989036192 | GL13: #N/A | GM13: 5117145648 | GN13: 5235333472 | GO13: #N/A | GP13: #N/A | GQ13: #N/A | GR13: #N/A | GS13: 7537775616 | GT13: #N/A | GU13: #N/A | GV13: #N/A | GW13: #N/A | GX13: #N/A | GY13: #N/A | GZ13: #N/A | HA13: #N/A | HB13: #N/A | HC13: #N/A | HD13: 968956672 | HE13: #N/A | HF13: 2329494624 | HG13: 10967729504 | HH13: #N/A | HI13: #N/A | HJ13: #N/A | HK13: 4128332560 | HL13: #N/A | HM13: #N/A | HN13: #N/A | HO13: 603983660 | HP13: #N/A | HQ13: 2021833928 | HR13: #N/A | HS13: #N/A | HT13: #N/A | HU13: 539657696 | HV13: #N/A | HW13: 2594323616 | HX13: #N/A | HY13: #N/A | HZ13: #N/A | IA13: #N/A | IB13: 515598752 | IC13: 676270528 | ID13: 4183498304 | IE13: 1519722624 | IF13: #N/A | IG13: #N/A | IH13: #N/A | II13: #N/A | IJ13: #N/A | IK13: 610669288 | IL13: 6930260672 | IM13: 233234925 | IN13: 850837654 | IO13: #N/A | IP13: 1656162616 | IQ13: #N/A | IR13: #N/A | IS13: #N/A | IT13: #N/A | IU13: 617881824 | IV13: 403471760 | IW13: #N/A | IX13: 1958356072 | IY13: #N/A | IZ13: #N/A | JA13: #N/A | JB13: 1060940680 | JC13: #N/A | JD13: #N/A | JE13: #N/A | JF13: #N/A | JG13: #N/A | JH13: 1738083384 | JI13: 8424930592 | JJ13: #N/A | JK13: #N/A | JL13: 2940623840 | JM13: 1580067104 | JN13: 635438880 | JO13: #N/A | JP13: 2625747048 | JQ13: 76958395 | JR13: 11342282752 | JS13: #N/A | JT13: #N/A | JU13: #N/A | JV13: #N/A | JW13: #N/A | JX13: 34102920 | JY13: #N/A | JZ13: #N/A | KA13: #N/A | KB13: #N/A | KC13: #N/A | KD13: #N/A | KE13: 801182904 | KF13: 1905445464 | KG13: #N/A | KH13: #N/A | KI13: #N/A
B14: 42156 | C14: 38681290288 | D14: 12527482336 | E14: #N/A | F14: 1561074224 | G14: 47107851512 | H14: #N/A | I14: 1604450016 | J14: #N/A | K14: #N/A | L14: #N/A | M14: #N/A | N14: #N/A | O14: #N/A | P14: #N/A | Q14: 1522421808 | R14: #N/A | S14: #N/A | T14: #N/A | U14: #N/A | V14: #N/A | W14: 11345896744 | X14: #N/A | Y14: 5038205328 | Z14: 1229205136 | AA14: #N/A | AB14: #N/A | AC14: 2090108760 | AD14: #N/A | AE14: #N/A | AF14: #N/A | AG14: 3049272224 | AH14: 13562851696 | AI14: #N/A | AJ14: #N/A | AK14: #N/A | AL14: 318500620160 | AM14: #N/A | AN14: #N/A | AO14: 5954824952 | AP14: 13514525584 | AQ14: 180150982464 | AR14: #N/A | AS14: 10858205248 | AT14: #N/A | AU14: 27750300096 | AV14: #N/A | AW14: 2019232552 | AX14: #N/A | AY14: #N/A | AZ14: #N/A | BA14: 8652439808 | BB14: 308985340864 | BC14: 318500620160 | BD14: 196524248384 | BE14: 213246282048 | BF14: 40010817920 | BG14: 91777147008 | BH14: 180150982464 | BI14: 1.3113824e+12 | BJ14: #N/A | BK14: 37211790624 | BL14: 47107851512 | BM14: 19107122176 | BN14: 4204128928 | BO14: #N/A | BP14: #N/A | BQ14: 61144626632 | BR14: 37217413088 | BS14: 20296836864 | BT14: 20499207616 | BU14: 27750300096 | BV14: 13514525584 | BW14: 11345896744 | BX14: 38681290288 | BY14: #N/A | BZ14: #N/A | CA14: 67073359616 | CB14: #N/A | CC14: #N/A | CD14: #N/A | CE14: #N/A | CF14: #N/A | CG14: 6956510080 | CH14: #N/A | CI14: #N/A | CJ14: 21261619832 | CK14: 5459848160 | CL14: 6034867784 | CM14: #N/A | CN14: #N/A | CO14: #N/A | CP14: 5954824952 | CQ14: 1921797048 | CR14: 10858205248 | CS14: 9607979056 | CT14: 45475757248 | CU14: 23092437264 | CV14: 870526944 | CW14: 13562851696 | CX14: #N/A | CY14: 73983264768 | CZ14: 6.953508e+10 | DA14: 3999358696 | DB14: #N/A | DC14: 371860304 | DD14: #N/A | DE14: 1561074224 | DF14: #N/A | DG14: #N/A | DH14: 6561309320 | DI14: 3299270344 | DJ14: #N/A | DK14: 5456957344 | DL14: #N/A | DM14: 1330181336 | DN14: 14115597152 | DO14: #N/A | DP14: 5657465312 | DQ14: #N/A | DR14: #N/A | DS14: #N/A | DT14: 3788878936 | DU14: 10262881632 | DV14: 3873011104 | DW14: 4013236120 | DX14: #N/A | DY14: #N/A | DZ14: 19749543032 | EA14: 2539489848 | EB14: #N/A | EC14: 5257069424 | ED14: 11830654576 | EE14: 1601611272 | EF14: 1681860000 | EG14: 4918133152 | EH14: 2616215936 | EI14: #N/A | EJ14: #N/A | EK14: 436313792 | EL14: #N/A | EM14: #N/A | EN14: #N/A | EO14: #N/A | EP14: 4997070104 | EQ14: #N/A | ER14: #N/A | ES14: #N/A | ET14: #N/A | EU14: 3201313456 | EV14: 2126210728 | EW14: #N/A | EX14: 12527482336 | EY14: #N/A | EZ14: 45403154 | FA14: 1522421808 | FB14: 5428026784 | FC14: #N/A | FD14: 2412555632 | FE14: #N/A | FF14: 935516520 | FG14: #N/A | FH14: #N/A | FI14: 19533371472 | FJ14: 2830801880 | FK14: #N/A | FL14: 624501760 | FM14: #N/A | FN14: 18418189904 | FO14: 8732652888 | FP14: #N/A | FQ14: #N/A | FR14: #N/A | FS14: #N/A | FT14: #N/A | FU14: 2196629504 | FV14: #N/A | FW14: 1100605448 | FX14: #N/A | FY14: #N/A | FZ14: #N/A | GA14: 1251577680 | GB14: #N/A | GC14: #N/A | GD14: 4293867000 | GE14: 1355924152 | GF14: 2019232552 | GG14: #N/A | GH14: 1555108744 | GI14: #N/A | GJ14: #N/A | GK14: 968402912 | GL14: #N/A | GM14: 4872117280 | GN14: 5189077856 | GO14: #N/A | GP14: #N/A | GQ14: #N/A | GR14: #N/A | GS14: 8023609856 | GT14: #N/A | GU14: #N/A | GV14: #N/A | GW14: #N/A | GX14: #N/A | GY14: #N/A | GZ14: #N/A | HA14: #N/A | HB14: #N/A | HC14: #N/A | HD14: 886514856 | HE14: #N/A | HF14: 1788128720 | HG14: 9767459680 | HH14: #N/A | HI14: #N/A | HJ14: #N/A | HK14: 4249406736 | HL14: #N/A | HM14: #N/A | HN14: #N/A | HO14: 724523844 | HP14: #N/A | HQ14: 2593317064 | HR14: #N/A | HS14: #N/A | HT14: #N/A | HU14: 558059088 | HV14: #N/A | HW14: 2791518512 | HX14: #N/A | HY14: #N/A | HZ14: #N/A | IA14: #N/A | IB14: 423133504 | IC14: 801170912 | ID14: 4222650432 | IE14: 1662838400 | IF14: #N/A | IG14: #N/A | IH14: #N/A | II14: #N/A | IJ14: #N/A | IK14: 376694936 | IL14: 6823783904 | IM14: 265958892 | IN14: 1071415321 | IO14: #N/A | IP14: 1740269904 | IQ14: #N/A | IR14: #N/A | IS14: #N/A | IT14: #N/A | IU14: 626286560 | IV14: 389310296 | IW14: #N/A | IX14: 2768394128 | IY14: #N/A | IZ14: #N/A | JA14: #N/A | JB14: 987897816 | JC14: #N/A | JD14: #N/A | JE14: #N/A | JF14: #N/A | JG14: #N/A | JH14: 2141686064 | JI14: 2231833824 | JJ14: #N/A | JK14: #N/A | JL14: 2977287240 | JM14: 1621698232 | JN14: 823291880 | JO14: #N/A | JP14: 3197856616 | JQ14: 79890387 | JR14: 10667911680 | JS14: #N/A | JT14: #N/A | JU14: #N/A | JV14: #N/A | JW14: #N/A | JX14: 35722328 | JY14: #N/A | JZ14: #N/A | KA14: #N/A | KB14: #N/A | KC14: #N/A | KD14: #N/A | KE14: 834113720 | KF14: 2072156304 | KG14: #N/A | KH14: #N/A | KI14: #N/A
B15: 42186 | C15: 38773035200 | D15: 11659687392 | E15: 512084752 | F15: 1683475120 | G15: 45428491512 | H15: #N/A | I15: 1779669856 | J15: #N/A | K15: #N/A | L15: #N/A | M15: #N/A | N15: #N/A | O15: #N/A | P15: #N/A | Q15: 1490002224 | R15: #N/A | S15: #N/A | T15: #N/A | U15: #N/A | V15: #N/A | W15: 11072133416 | X15: #N/A | Y15: 5006008720 | Z15: 1216641424 | AA15: #N/A | AB15: #N/A | AC15: 2594270680 | AD15: #N/A | AE15: #N/A | AF15: #N/A | AG15: 3294546848 | AH15: 13073354096 | AI15: #N/A | AJ15: #N/A | AK15: #N/A | AL15: 295971178368 | AM15: #N/A | AN15: #N/A | AO15: 6195604216 | AP15: 13986366352 | AQ15: 162508750912 | AR15: #N/A | AS15: 9946458176 | AT15: #N/A | AU15: 26428469696 | AV15: #N/A | AW15: 2003472424 | AX15: #N/A | AY15: #N/A | AZ15: #N/A | BA15: 7587200256 | BB15: 302656496576 | BC15: 295971178368 | BD15: 199537200448 | BE15: 231836813632 | BF15: 37583376768 | BG15: 98269134976 | BH15: 162508750912 | BI15: 1.20885e+12 | BJ15: #N/A | BK15: 39177800992 | BL15: 45428491512 | BM15: 19184352256 | BN15: 5004465824 | BO15: #N/A | BP15: #N/A | BQ15: 60299163080 | BR15: 35537911776 | BS15: 18952835840 | BT15: 23161088448 | BU15: 26428469696 | BV15: 13986366352 | BW15: 11072133416 | BX15: 38773035200 | BY15: #N/A | BZ15: #N/A | CA15: 67144064768 | CB15: #N/A | CC15: #N/A | CD15: #N/A | CE15: #N/A | CF15: #N/A | CG15: 7006137728 | CH15: #N/A | CI15: #N/A | CJ15: 21219007352 | CK15: 5366192608 | CL15: 5879449160 | CM15: #N/A | CN15: #N/A | CO15: #N/A | CP15: 6195604216 | CQ15: 1779490104 | CR15: 9946458176 | CS15: 8458362928 | CT15: 46954061504 | CU15: 22874500112 | CV15: 885857312 | CW15: 13073354096 | CX15: #N/A | CY15: 71389620224 | CZ15: 6.2949397e+10 | DA15: 4032290792 | DB15: #N/A | DC15: 464591824 | DD15: #N/A | DE15: 1683475120 | DF15: #N/A | DG15: #N/A | DH15: 6347619464 | DI15: 3404535240 | DJ15: #N/A | DK15: 5861553056 | DL15: #N/A | DM15: 2054829960 | DN15: 14082430816 | DO15: #N/A | DP15: 6245852128 | DQ15: #N/A | DR15: #N/A | DS15: #N/A | DT15: 3399710808 | DU15: 9798748512 | DV15: 3664507552 | DW15: 4224221848 | DX15: #N/A | DY15: #N/A | DZ15: 18813148280 | EA15: 2708152504 | EB15: #N/A | EC15: 5228946464 | ED15: 11009068656 | EE15: 1367175048 | EF15: 1738610976 | EG15: 4704070816 | EH15: 2552203008 | EI15: #N/A | EJ15: #N/A | EK15: 451901440 | EL15: #N/A | EM15: #N/A | EN15: #N/A | EO15: #N/A | EP15: 4776342296 | EQ15: #N/A | ER15: #N/A | ES15: #N/A | ET15: #N/A | EU15: 3703570096 | EV15: 2892182952 | EW15: #N/A | EX15: 11659687392 | EY15: #N/A | EZ15: 53782930 | FA15: 1490002224 | FB15: 5614424480 | FC15: #N/A | FD15: 2587742448 | FE15: #N/A | FF15: 945317800 | FG15: #N/A | FH15: #N/A | FI15: 21569646672 | FJ15: 3203885784 | FK15: #N/A | FL15: 601775712 | FM15: #N/A | FN15: 18746725968 | FO15: 8358879576 | FP15: #N/A | FQ15: #N/A | FR15: #N/A | FS15: #N/A | FT15: #N/A | FU15: 2784572160 | FV15: #N/A | FW15: 1131604936 | FX15: #N/A | FY15: #N/A | FZ15: 929585328 | GA15: 1198523216 | GB15: #N/A | GC15: #N/A | GD15: 4414301944 | GE15: 1700787320 | GF15: 2003472424 | GG15: #N/A | GH15: 1707994888 | GI15: #N/A | GJ15: #N/A | GK15: 958398880 | GL15: #N/A | GM15: 4237348384 | GN15: 5296044384 | GO15: #N/A | GP15: #N/A | GQ15: #N/A | GR15: #N/A | GS15: 7791562752 | GT15: #N/A | GU15: #N/A | GV15: #N/A | GW15: #N/A | GX15: #N/A | GY15: #N/A | GZ15: #N/A | HA15: #N/A | HB15: #N/A | HC15: #N/A | HD15: 898467592 | HE15: #N/A | HF15: 1560088144 | HG15: 8190874976 | HH15: #N/A | HI15: #N/A | HJ15: #N/A | HK15: 4369364496 | HL15: #N/A | HM15: #N/A | HN15: #N/A | HO15: 738701444 | HP15: #N/A | HQ15: 2400883656 | HR15: #N/A | HS15: #N/A | HT15: #N/A | HU15: 597154960 | HV15: #N/A | HW15: 2115456048 | HX15: #N/A | HY15: #N/A | HZ15: #N/A | IA15: #N/A | IB15: 385533504 | IC15: 904927648 | ID15: 4028520256 | IE15: 1560249216 | IF15: #N/A | IG15: #N/A | IH15: #N/A | II15: #N/A | IJ15: #N/A | IK15: 441294712 | IL15: 6937193952 | IM15: 282360844 | IN15: 1093790361 | IO15: #N/A | IP15: 1770637264 | IQ15: #N/A | IR15: #N/A | IS15: #N/A | IT15: #N/A | IU15: 703799264 | IV15: 392480888 | IW15: #N/A | IX15: 3386278032 | IY15: #N/A | IZ15: #N/A | JA15: #N/A | JB15: 1044405336 | JC15: #N/A | JD15: #N/A | JE15: #N/A | JF15: #N/A | JG15: #N/A | JH15: 2311660464 | JI15: 2055850208 | JJ15: #N/A | JK15: #N/A | JL15: 3254060360 | JM15: 1750047928 | JN15: 1018372136 | JO15: #N/A | JP15: 2826172520 | JQ15: 83500283 | JR15: 12158975488 | JS15: #N/A | JT15: #N/A | JU15: #N/A | JV15: #N/A | JW15: #N/A | JX15: 53242368 | JY15: #N/A | JZ15: #N/A | KA15: #N/A | KB15: #N/A | KC15: #N/A | KD15: #N/A | KE15: 796329912 | KF15: 2000243344 | KG15: #N/A | KH15: #N/A | KI15: #N/A
B16: 42217 | C16: 39293071552 | D16: 12786770088 | E16: 553038032 | F16: 1368357048 | G16: 47239050488 | H16: #N/A | I16: 1680264032 | J16: #N/A | K16: #N/A | L16: #N/A | M16: #N/A | N16: #N/A | O16: #N/A | P16: #N/A | Q16: 1648791856 | R16: #N/A | S16: #N/A | T16: #N/A | U16: #N/A | V16: #N/A | W16: 12117387352 | X16: #N/A | Y16: 4529079480 | Z16: 1112057488 | AA16: #N/A | AB16: #N/A | AC16: 2625599544 | AD16: #N/A | AE16: #N/A | AF16: #N/A | AG16: 3118011296 | AH16: 14683483504 | AI16: #N/A | AJ16: #N/A | AK16: #N/A | AL16: 312271720320 | AM16: #N/A | AN16: #N/A | AO16: 7221911624 | AP16: 14797030288 | AQ16: 161207926848 | AR16: #N/A | AS16: 9990850624 | AT16: #N/A | AU16: 27572494784 | AV16: #N/A | AW16: 1858712360 | AX16: #N/A | AY16: #N/A | AZ16: #N/A | BA16: 7345100032 | BB16: 374399856960 | BC16: 312271720320 | BD16: 246270821632 | BE16: 250901457408 | BF16: 34892575104 | BG16: 97486361728 | BH16: 161207926848 | BI16: 1.1466335e+12 | BJ16: #N/A | BK16: 48112145424 | BL16: 47239050488 | BM16: 18826374304 | BN16: 5179435680 | BO16: #N/A | BP16: #N/A | BQ16: 65131390408 | BR16: 36596803552 | BS16: 15122869184 | BT16: 17998103936 | BU16: 27572494784 | BV16: 14797030288 | BW16: 12117387352 | BX16: 39293071552 | BY16: #N/A | BZ16: #N/A | CA16: 67528526592 | CB16: #N/A | CC16: #N/A | CD16: #N/A | CE16: #N/A | CF16: #N/A | CG16: 7099190144 | CH16: #N/A | CI16: #N/A | CJ16: 20970150520 | CK16: 5714560720 | CL16: 5650411080 | CM16: #N/A | CN16: #N/A | CO16: #N/A | CP16: 7221911624 | CQ16: 1813046256 | CR16: 9990850624 | CS16: 9289390128 | CT16: 49818828480 | CU16: 22929513488 | CV16: 1034040664 | CW16: 14683483504 | CX16: #N/A | CY16: 31324576512 | CZ16: 6.3563196e+10 | DA16: 3734823400 | DB16: #N/A | DC16: 570656216 | DD16: 42859067264 | DE16: 1368357048 | DF16: #N/A | DG16: #N/A | DH16: 6071435400 | DI16: 3377628760 | DJ16: #N/A | DK16: 5895189408 | DL16: #N/A | DM16: 1990469512 | DN16: 15392979992 | DO16: #N/A | DP16: 6632823264 | DQ16: #N/A | DR16: #N/A | DS16: #N/A | DT16: 3224283224 | DU16: 8234863392 | DV16: 2967529376 | DW16: 3929153360 | DX16: #N/A | DY16: #N/A | DZ16: 18782710904 | EA16: 2549465528 | EB16: #N/A | EC16: 5447648032 | ED16: 10997018096 | EE16: 1197964936 | EF16: 1958237088 | EG16: 3726951488 | EH16: 2429264736 | EI16: #N/A | EJ16: #N/A | EK16: 445170368 | EL16: #N/A | EM16: #N/A | EN16: #N/A | EO16: #N/A | EP16: 4385959704 | EQ16: #N/A | ER16: #N/A | ES16: #N/A | ET16: #N/A | EU16: 3919800160 | EV16: 2836217768 | EW16: #N/A | EX16: 12786770088 | EY16: #N/A | EZ16: 53986930 | FA16: 1648791856 | FB16: 5637724064 | FC16: #N/A | FD16: 2675676656 | FE16: #N/A | FF16: 1527634536 | FG16: #N/A | FH16: #N/A | FI16: 23099261008 | FJ16: 3615888344 | FK16: #N/A | FL16: 582017664 | FM16: #N/A | FN16: 20178040400 | FO16: 7660515040 | FP16: #N/A | FQ16: #N/A | FR16: #N/A | FS16: #N/A | FT16: #N/A | FU16: 2891470592 | FV16: #N/A | FW16: 1048939656 | FX16: #N/A | FY16: #N/A | FZ16: 1109360944 | GA16: 1162792784 | GB16: #N/A | GC16: #N/A | GD16: 4534737144 | GE16: 1794379512 | GF16: 1858712360 | GG16: #N/A | GH16: 1725207304 | GI16: #N/A | GJ16: #N/A | GK16: 947744544 | GL16: #N/A | GM16: 3961361952 | GN16: 5475395168 | GO16: #N/A | GP16: #N/A | GQ16: #N/A | GR16: #N/A | GS16: 8910888640 | GT16: #N/A | GU16: #N/A | GV16: #N/A | GW16: #N/A | GX16: #N/A | GY16: #N/A | GZ16: #N/A | HA16: #N/A | HB16: #N/A | HC16: #N/A | HD16: 898467592 | HE16: #N/A | HF16: 2323576784 | HG16: 7480684008 | HH16: #N/A | HI16: #N/A | HJ16: #N/A | HK16: 4520857872 | HL16: #N/A | HM16: #N/A | HN16: #N/A | HO16: 778702404 | HP16: #N/A | HQ16: 2419873200 | HR16: #N/A | HS16: #N/A | HT16: #N/A | HU16: 566212752 | HV16: #N/A | HW16: 2405818416 | HX16: #N/A | HY16: #N/A | HZ16: #N/A | IA16: #N/A | IB16: 395509024 | IC16: 891911584 | ID16: 3635791936 | IE16: 1539221632 | IF16: #N/A | IG16: #N/A | IH16: #N/A | II16: #N/A | IJ16: #N/A | IK16: 403528696 | IL16: 7090296800 | IM16: 337307468 | IN16: 1071117465 | IO16: #N/A | IP16: 1560154320 | IQ16: #N/A | IR16: #N/A | IS16: #N/A | IT16: #N/A | IU16: 762305464 | IV16: 331894472 | IW16: #N/A | IX16: 4325524880 | IY16: #N/A | IZ16: #N/A | JA16: #N/A | JB16: 922565400 | JC16: #N/A | JD16: #N/A | JE16: #N/A | JF16: #N/A | JG16: #N/A | JH16: 1785354288 | JI16: 2041385696 | JJ16: #N/A | JK16: #N/A | JL16: 3859473536 | JM16: 1798812984 | JN16: 1085091112 | JO16: #N/A | JP16: 1626611944 | JQ16: 88657267 | JR16: 10980369792 | JS16: #N/A | JT16: #N/A | JU16: #N/A | JV16: #N/A | JW16: #N/A | JX16: 53952640 | JY16: #N/A | JZ16: #N/A | KA16: #N/A | KB16: #N/A | KC16: #N/A | KD16: #N/A | KE16: 863560008 | KF16: 1733138448 | KG16: #N/A | KH16: #N/A | KI16: #N/A
B17: 42248 | C17: 36307202240 | D17: 11667989672 | E17: 449888488 | F17: 1125782200 | G17: 43706060784 | H17: #N/A | I17: 1307308400 | J17: #N/A | K17: #N/A | L17: #N/A | M17: #N/A | N17: #N/A | O17: #N/A | P17: #N/A | Q17: 1421330160 | R17: #N/A | S17: #N/A | T17: #N/A | U17: #N/A | V17: #N/A | W17: 10494899288 | X17: #N/A | Y17: 4035824312 | Z17: 792322576 | AA17: #N/A | AB17: #N/A | AC17: 1814929720 | AD17: #N/A | AE17: #N/A | AF17: #N/A | AG17: 2814765672 | AH17: 11887548984 | AI17: #N/A | AJ17: #N/A | AK17: #N/A | AL17: 273241558912 | AM17: #N/A | AN17: #N/A | AO17: 6120220744 | AP17: 12790867856 | AQ17: 144167141440 | AR17: #N/A | AS17: 8823595072 | AT17: #N/A | AU17: 22124485312 | AV17: #N/A | AW17: 2185502920 | AX17: #N/A | AY17: #N/A | AZ17: #N/A | BA17: 8526840448 | BB17: 355290378560 | BC17: 273241558912 | BD17: 227744826624 | BE17: 231798499840 | BF17: 33610934720 | BG17: 92265133184 | BH17: 144167141440 | BI17: 9.4689395e+11 | BJ17: #N/A | BK17: 44496573456 | BL17: 43706060784 | BM17: 16974934176 | BN17: 4342769096 | BO17: #N/A | BP17: #N/A | BQ17: 63832576848 | BR17: 34812277152 | BS17: 14890085312 | BT17: 21865235584 | BU17: 22124485312 | BV17: 12790867856 | BW17: 10494899288 | BX17: 36307202240 | BY17: #N/A | BZ17: #N/A | CA17: 68574947672 | CB17: #N/A | CC17: #N/A | CD17: #N/A | CE17: #N/A | CF17: #N/A | CG17: 6207020488 | CH17: #N/A | CI17: #N/A | CJ17: 4224671512 | CK17: 5350335696 | CL17: 4743252704 | CM17: #N/A | CN17: #N/A | CO17: #N/A | CP17: 6120220744 | CQ17: 1619142640 | CR17: 8823595072 | CS17: 6887021056 | CT17: 45485874880 | CU17: 21233865448 | CV17: 1028783704 | CW17: 11887548984 | CX17: #N/A | CY17: 29326680832 | CZ17: 6.2328529e+10 | DA17: 3472636320 | DB17: #N/A | DC17: 525306648 | DD17: 36850702208 | DE17: 1125782200 | DF17: #N/A | DG17: #N/A | DH17: 5798026312 | DI17: 3117004632 | DJ17: #N/A | DK17: 5068513480 | DL17: #N/A | DM17: 1184973896 | DN17: 13962823704 | DO17: #N/A | DP17: 6938761344 | DQ17: #N/A | DR17: #N/A | DS17: #N/A | DT17: 3293187040 | DU17: 8345010464 | DV17: 2744994664 | DW17: 3592174928 | DX17: #N/A | DY17: #N/A | DZ17: 20809646464 | EA17: 2467244568 | EB17: #N/A | EC17: 5331060600 | ED17: 10358601200 | EE17: 1169897648 | EF17: 1650883432 | EG17: 3427716800 | EH17: 2395884640 | EI17: #N/A | EJ17: #N/A | EK17: 482483264 | EL17: #N/A | EM17: #N/A | EN17: #N/A | EO17: #N/A | EP17: 3980828200 | EQ17: #N/A | ER17: #N/A | ES17: #N/A | ET17: #N/A | EU17: 3656169568 | EV17: 2766853352 | EW17: #N/A | EX17: 11667989672 | EY17: #N/A | EZ17: 40114930 | FA17: 1421330160 | FB17: 4897969088 | FC17: #N/A | FD17: 2841377200 | FE17: #N/A | FF17: 1557042080 | FG17: #N/A | FH17: #N/A | FI17: 20057099448 | FJ17: 3283128008 | FK17: #N/A | FL17: 505559904 | FM17: #N/A | FN17: 18412074856 | FO17: 7095034592 | FP17: #N/A | FQ17: #N/A | FR17: #N/A | FS17: #N/A | FT17: #N/A | FU17: 2032605848 | FV17: #N/A | FW17: 1071617624 | FX17: #N/A | FY17: #N/A | FZ17: 861029096 | GA17: 1030605944 | GB17: 2285658664 | GC17: #N/A | GD17: 4074672472 | GE17: 1541396984 | GF17: 2185502920 | GG17: #N/A | GH17: 1546119920 | GI17: #N/A | GJ17: #N/A | GK17: 866490720 | GL17: #N/A | GM17: 3283011608 | GN17: 4981778016 | GO17: #N/A | GP17: #N/A | GQ17: #N/A | GR17: #N/A | GS17: 9076697664 | GT17: #N/A | GU17: #N/A | GV17: #N/A | GW17: #N/A | GX17: #N/A | GY17: #N/A | GZ17: #N/A | HA17: #N/A | HB17: #N/A | HC17: #N/A | HD17: 907430048 | HE17: #N/A | HF17: 1294569080 | HG17: 6960844776 | HH17: #N/A | HI17: #N/A | HJ17: #N/A | HK17: 4507310968 | HL17: #N/A | HM17: #N/A | HN17: #N/A | HO17: 526710900 | HP17: #N/A | HQ17: 2301538480 | HR17: #N/A | HS17: #N/A | HT17: #N/A | HU17: 545397920 | HV17: #N/A | HW17: 1688051392 | HX17: #N/A | HY17: #N/A | HZ17: #N/A | IA17: #N/A | IB17: 336766576 | IC17: 842155472 | ID17: 3356905280 | IE17: 1263708664 | IF17: #N/A | IG17: #N/A | IH17: #N/A | II17: #N/A | IJ17: #N/A | IK17: 383054016 | IL17: 6690067968 | IM17: 238491451 | IN17: 898379952 | IO17: #N/A | IP17: 1297285728 | IQ17: #N/A | IR17: #N/A | IS17: #N/A | IT17: #N/A | IU17: 704020280 | IV17: 338133320 | IW17: #N/A | IX17: 3970737464 | IY17: #N/A | IZ17: #N/A | JA17: #N/A | JB17: 797118536 | JC17: #N/A | JD17: #N/A | JE17: #N/A | JF17: #N/A | JG17: #N/A | JH17: 1578235664 | JI17: 1912164448 | JJ17: #N/A | JK17: #N/A | JL17: 3571826816 | JM17: 1640423992 | JN17: 757380856 | JO17: #N/A | JP17: 1392783224 | JQ17: 65260527 | JR17: 9367931264 | JS17: #N/A | JT17: #N/A | JU17: #N/A | JV17: #N/A | JW17: #N/A | JX17: 61702120 | JY17: #N/A | JZ17: #N/A | KA17: #N/A | KB17: #N/A | KC17: #N/A | KD17: #N/A | KE17: 732415816 | KF17: 1520823224 | KG17: #N/A | KH17: #N/A | KI17: #N/A
B18: 42278 | C18: 40011805544 | D18: 11405454504 | E18: 508558760 | F18: 1111234232 | G18: 47850860528 | H18: #N/A | I18: 1335167344 | J18: #N/A | K18: #N/A | L18: #N/A | M18: #N/A | N18: #N/A | O18: #N/A | P18: #N/A | Q18: 1434494448 | R18: #N/A | S18: #N/A | T18: #N/A | U18: #N/A | V18: #N/A | W18: 10910125144 | X18: #N/A | Y18: 3934214072 | Z18: 850957648 | AA18: #N/A | AB18: #N/A | AC18: 2649859896 | AD18: #N/A | AE18: #N/A | AF18: #N/A | AG18: 2660508776 | AH18: 12458259000 | AI18: #N/A | AJ18: #N/A | AK18: #N/A | AL18: 295555944320 | AM18: #N/A | AN18: #N/A | AO18: 6493331016 | AP18: 13751889664 | AQ18: 141111140928 | AR18: #N/A | AS18: 8292027456 | AT18: #N/A | AU18: 23444466368 | AV18: #N/A | AW18: 2110305608 | AX18: #N/A | AY18: #N/A | AZ18: #N/A | BA18: 9933630080 | BB18: 364210385216 | BC18: 295555944320 | BD18: 239054062848 | BE18: 242279770624 | BF18: 36317491648 | BG18: 98229081216 | BH18: 141111140928 | BI18: 8.5007036e+11 | BJ18: #N/A | BK18: 44577203216 | BL18: 47850860528 | BM18: 16866732192 | BN18: 3607164616 | BO18: #N/A | BP18: #N/A | BQ18: 65440826192 | BR18: 36680786336 | BS18: 14419226048 | BT18: 22781713536 | BU18: 23444466368 | BV18: 13751889664 | BW18: 10910125144 | BX18: 40011805544 | BY18: #N/A | BZ18: #N/A | CA18: 67962408792 | CB18: #N/A | CC18: #N/A | CD18: #N/A | CE18: #N/A | CF18: #N/A | CG18: 6325540296 | CH18: #N/A | CI18: #N/A | CJ18: 4100730392 | CK18: 5583439568 | CL18: 5024722656 | CM18: #N/A | CN18: #N/A | CO18: #N/A | CP18: 6493331016 | CQ18: 1765667696 | CR18: 8292027456 | CS18: 5342794752 | CT18: 46385797184 | CU18: 21405259752 | CV18: 1027657176 | CW18: 12458259000 | CX18: #N/A | CY18: 27414063872 | CZ18: 6.0701472e+10 | DA18: 3459428000 | DB18: #N/A | DC18: 490370648 | DD18: 34059798400 | DE18: 1111234232 | DF18: #N/A | DG18: #N/A | DH18: 5818262600 | DI18: 3198897240 | DJ18: #N/A | DK18: 5067560904 | DL18: #N/A | DM18: 1110770056 | DN18: 15196696600 | DO18: #N/A | DP18: 6767386752 | DQ18: #N/A | DR18: #N/A | DS18: #N/A | DT18: 2831052768 | DU18: 7562504992 | DV18: 2664346984 | DW18: 3350567504 | DX18: #N/A | DY18: #N/A | DZ18: 21316802944 | EA18: 2479220504 | EB18: #N/A | EC18: 5151698808 | ED18: 10848717296 | EE18: 1263669552 | EF18: 1535386472 | EG18: 2972312256 | EH18: 2015408480 | EI18: #N/A | EJ18: #N/A | EK18: 434638336 | EL18: #N/A | EM18: #N/A | EN18: #N/A | EO18: #N/A | EP18: 4313334824 | EQ18: #N/A | ER18: #N/A | ES18: 1342825904 | ET18: #N/A | EU18: 3132343136 | EV18: 2716567784 | EW18: #N/A | EX18: 11405454504 | EY18: #N/A | EZ18: 43582930 | FA18: 1434494448 | FB18: 4955467200 | FC18: #N/A | FD18: 2858108336 | FE18: #N/A | FF18: 1586348064 | FG18: #N/A | FH18: #N/A | FI18: 17666462904 | FJ18: 3168997576 | FK18: #N/A | FL18: 481035712 | FM18: #N/A | FN18: 18730597224 | FO18: 6784286944 | FP18: #N/A | FQ18: #N/A | FR18: #N/A | FS18: #N/A | FT18: #N/A | FU18: 1649290520 | FV18: #N/A | FW18: 1038028504 | FX18: #N/A | FY18: #N/A | FZ18: 781287592 | GA18: 996983032 | GB18: 2077406720 | GC18: #N/A | GD18: 4005551448 | GE18: 1508223760 | GF18: 2110305608 | GG18: #N/A | GH18: 1428673392 | GI18: #N/A | GJ18: #N/A | GK18: 854615136 | GL18: #N/A | GM18: 3431983640 | GN18: 4785102432 | GO18: #N/A | GP18: #N/A | GQ18: #N/A | GR18: #N/A | GS18: 9768056384 | GT18: #N/A | GU18: #N/A | GV18: #N/A | GW18: #N/A | GX18: #N/A | GY18: #N/A | GZ18: #N/A | HA18: #N/A | HB18: #N/A | HC18: #N/A | HD18: 878971600 | HE18: #N/A | HF18: 1304639736 | HG18: 5790634088 | HH18: #N/A | HI18: #N/A | HJ18: #N/A | HK18: 4720320376 | HL18: #N/A | HM18: #N/A | HN18: #N/A | HO18: 445262644 | HP18: #N/A | HQ18: 2427425408 | HR18: #N/A | HS18: #N/A | HT18: #N/A | HU18: 494270240 | HV18: #N/A | HW18: 1648176448 | HX18: #N/A | HY18: #N/A | HZ18: #N/A | IA18: #N/A | IB18: 326041360 | IC18: 819530448 | ID18: 3201433920 | IE18: 1337383800 | IF18: #N/A | IG18: #N/A | IH18: #N/A | II18: #N/A | IJ18: #N/A | IK18: 270415520 | IL18: 6610673664 | IM18: 173381195 | IN18: 690695472 | IO18: #N/A | IP18: 1070633568 | IQ18: #N/A | IR18: #N/A | IS18: #N/A | IT18: #N/A | IU18: 668544184 | IV18: 305345048 | IW18: #N/A | IX18: 3502688568 | IY18: #N/A | IZ18: #N/A | JA18: #N/A | JB18: 763361800 | JC18: #N/A | JD18: #N/A | JE18: #N/A | JF18: #N/A | JG18: #N/A | JH18: 1319622800 | JI18: 1769930976 | JJ18: #N/A | JK18: #N/A | JL18: 3948620160 | JM18: 1540911152 | JN18: 785944184 | JO18: #N/A | JP18: 1202393592 | JQ18: 60748159 | JR18: 8782900608 | JS18: #N/A | JT18: #N/A | JU18: #N/A | JV18: #N/A | JW18: #N/A | JX18: 29011740 | JY18: #N/A | JZ18: #N/A | KA18: #N/A | KB18: #N/A | KC18: #N/A | KD18: #N/A | KE18: 720844296 | KF18: 1457323192 | KG18: #N/A | KH18: #N/A | KI18: #N/A
B19: 42309 | C19: 42460910440 | D19: 9976652896 | E19: 526662696 | F19: 1174814648 | G19: 51018862576 | H19: #N/A | I19: 1287680496 | J19: #N/A | K19: #N/A | L19: #N/A | M19: #N/A | N19: #N/A | O19: #N/A | P19: #N/A | Q19: 1641748976 | R19: #N/A | S19: #N/A | T19: #N/A | U19: #N/A | V19: #N/A | W19: 12483445184 | X19: #N/A | Y19: 4395455928 | Z19: 1045953104 | AA19: #N/A | AB19: #N/A | AC19: 2425637176 | AD19: #N/A | AE19: #N/A | AF19: #N/A | AG19: 2921363304 | AH19: 13758099000 | AI19: #N/A | AJ19: #N/A | AK19: #N/A | AL19: 359695760128 | AM19: #N/A | AN19: #N/A | AO19: 4972605392 | AP19: 12845694720 | AQ19: 152199160384 | AR19: #N/A | AS19: 11017726016 | AT19: #N/A | AU19: 25820984000 | AV19: #N/A | AW19: 2230293192 | AX19: #N/A | AY19: #N/A | AZ19: #N/A | BA19: 12197429888 | BB19: 429725805568 | BC19: 359695760128 | BD19: 288330118400 | BE19: 273329105408 | BF19: 36590729664 | BG19: 94165001216 | BH19: 152199160384 | BI19: 1.2627066e+12 | BJ19: #N/A | BK19: 46110698992 | BL19: 51018862576 | BM19: 18055758400 | BN19: 3843825608 | BO19: #N/A | BP19: #N/A | BQ19: 75944174416 | BR19: 35794995120 | BS19: 16683626176 | BT19: 17879102400 | BU19: 25820984000 | BV19: 12845694720 | BW19: 12483445184 | BX19: 42460910440 | BY19: #N/A | BZ19: #N/A | CA19: 67957904728 | CB19: #N/A | CC19: #N/A | CD19: #N/A | CE19: #N/A | CF19: #N/A | CG19: 6883832264 | CH19: #N/A | CI19: #N/A | CJ19: 4217688856 | CK19: 6247926344 | CL19: 4123231968 | CM19: #N/A | CN19: #N/A | CO19: #N/A | CP19: 4972605392 | CQ19: 2237128168 | CR19: 11017726016 | CS19: 5875870208 | CT19: 49767110720 | CU19: 21081514984 | CV19: 1180987824 | CW19: 13758099000 | CX19: #N/A | CY19: 35636245120 | CZ19: 1.1430012e+11 | DA19: 3514750624 | DB19: #N/A | DC19: 533161632 | DD19: 39694059328 | DE19: 1174814648 | DF19: #N/A | DG19: #N/A | DH19: 6958287760 | DI19: 3429940312 | DJ19: #N/A | DK19: 5484450696 | DL19: #N/A | DM19: 1113041608 | DN19: 19314311152 | DO19: #N/A | DP19: 6578394240 | DQ19: #N/A | DR19: #N/A | DS19: #N/A | DT19: 4234478784 | DU19: 8314277024 | DV19: 2772533096 | DW19: 3683731280 | DX19: #N/A | DY19: #N/A | DZ19: 21244608896 | EA19: 2553471512 | EB19: #N/A | EC19: 4947467640 | ED19: 11749480784 | EE19: 1324649216 | EF19: 1736794984 | EG19: 3025357568 | EH19: 2216629632 | EI19: #N/A | EJ19: #N/A | EK19: 559960576 | EL19: #N/A | EM19: #N/A | EN19: #N/A | EO19: #N/A | EP19: 4679554088 | EQ19: #N/A | ER19: #N/A | ES19: 1251522736 | ET19: #N/A | EU19: 3855028256 | EV19: 3254623976 | EW19: #N/A | EX19: 9976652896 | EY19: #N/A | EZ19: 40318930 | FA19: 1641748976 | FB19: 5295793344 | FC19: #N/A | FD19: 2972747440 | FE19: #N/A | FF19: 1651723040 | FG19: #N/A | FH19: #N/A | FI19: 18903918296 | FJ19: 3563869640 | FK19: #N/A | FL19: 492701568 | FM19: #N/A | FN19: 20169678696 | FO19: 7524425480 | FP19: #N/A | FQ19: #N/A | FR19: #N/A | FS19: #N/A | FT19: #N/A | FU19: 1908667288 | FV19: #N/A | FW19: 1180136280 | FX19: #N/A | FY19: #N/A | FZ19: 756707752 | GA19: 1066398072 | GB19: 2092213120 | GC19: #N/A | GD19: 3864324280 | GE19: 1722807312 | GF19: 2230293192 | GG19: #N/A | GH19: 1639670128 | GI19: #N/A | GJ19: #N/A | GK19: 953994848 | GL19: #N/A | GM19: 3321406488 | GN19: 4929895296 | GO19: #N/A | GP19: #N/A | GQ19: #N/A | GR19: #N/A | GS19: 8703314624 | GT19: #N/A | GU19: #N/A | GV19: #N/A | GW19: #N/A | GX19: #N/A | GY19: #N/A | GZ19: #N/A | HA19: #N/A | HB19: #N/A | HC19: #N/A | HD19: 937222496 | HE19: #N/A | HF19: 940976760 | HG19: 5331095976 | HH19: #N/A | HI19: #N/A | HJ19: #N/A | HK19: 4726389112 | HL19: #N/A | HM19: #N/A | HN19: #N/A | HO19: 558239284 | HP19: #N/A | HQ19: 2281446784 | HR19: #N/A | HS19: #N/A | HT19: #N/A | HU19: 426520736 | HV19: #N/A | HW19: 1590176448 | HX19: #N/A | HY19: #N/A | HZ19: #N/A | IA19: #N/A | IB19: 264145544 | IC19: 829526480 | ID19: 3301655872 | IE19: 1060167336 | IF19: #N/A | IG19: #N/A | IH19: #N/A | II19: #N/A | IJ19: #N/A | IK19: 293092736 | IL19: 6984960000 | IM19: 200093083 | IN19: 634931696 | IO19: #N/A | IP19: 1068400928 | IQ19: #N/A | IR19: #N/A | IS19: #N/A | IT19: #N/A | IU19: 708487672 | IV19: 330465096 | IW19: #N/A | IX19: 3517000760 | IY19: #N/A | IZ19: #N/A | JA19: #N/A | JB19: 807088872 | JC19: #N/A | JD19: #N/A | JE19: #N/A | JF19: #N/A | JG19: #N/A | JH19: 1415017104 | JI19: 1796448992 | JJ19: #N/A | JK19: #N/A | JL19: 3634916272 | JM19: 1564763696 | JN19: 594057016 | JO19: #N/A | JP19: 1310420104 | JQ19: 55423567 | JR19: 11614393728 | JS19: #N/A | JT19: #N/A | JU19: #N/A | JV19: #N/A | JW19: #N/A | JX19: 31745844 | JY19: #N/A | JZ19: #N/A | KA19: #N/A | KB19: #N/A | KC19: #N/A | KD19: #N/A | KE19: 1040637376 | KF19: 1393823032 | KG19: #N/A | KH19: #N/A | KI19: #N/A
